5:return {{["x"] = 0, ["y"] = 0, ["param1"] = 15, ["z"] = 0, ["name"] = "default:stone"}, {["x"] = 0, ["y"] = 0, ["param1"] = 15, ["z"] = 1, ["name"] = "default:stone"}, {["x"] = 0, ["y"] = 0, ["param1"] = 15, ["z"] = 2, ["name"] = "default:stone"}, {["x"] = 0, ["y"] = 0, ["param1"] = 15, ["z"] = 3, ["name"] = "default:stone"}, {["x"] = 0, ["y"] = 0, ["param1"] = 15, ["z"] = 4, ["name"] = "default:stone"}, {["x"] = 0, ["y"] = 0, ["param1"] = 15, ["z"] = 5, ["name"] = "default:stone"}, {["x"] = 0, ["y"] = 0, ["param1"] = 15, ["z"] = 6, ["name"] = "default:stone"}, {["x"] = 0, ["y"] = 0, ["param1"] = 15, ["z"] = 7, ["name"] = "default:stone"}, {["x"] = 0, ["y"] = 0, ["param1"] = 15, ["z"] = 8, ["name"] = "default:stone"}, {["x"] = 0, ["y"] = 0, ["param1"] = 15, ["z"] = 9, ["name"] = "default:stone"}, {["x"] = 0, ["y"] = 0, ["param1"] = 15, ["z"] = 10, ["name"] = "default:stone"}, {["x"] = 0, ["y"] = 1, ["z"] = 0, ["name"] = "default:stone"}, {["x"] = 0, ["y"] = 1, ["z"] = 10, ["name"] = "default:stone"}, {["x"] = 0, ["y"] = 2, ["z"] = 0, ["name"] = "default:stone"}, {["x"] = 0, ["y"] = 2, ["z"] = 10, ["name"] = "default:stone"}, {["x"] = 0, ["y"] = 3, ["z"] = 0, ["name"] = "default:stone"}, {["x"] = 0, ["y"] = 3, ["z"] = 10, ["name"] = "default:stone"}, {["x"] = 0, ["y"] = 4, ["z"] = 0, ["name"] = "default:stone"}, {["x"] = 0, ["y"] = 4, ["z"] = 10, ["name"] = "default:stone"}, {["x"] = 0, ["y"] = 5, ["z"] = 0, ["name"] = "default:stone"}, {["x"] = 0, ["y"] = 5, ["z"] = 10, ["name"] = "default:stone"}, {["x"] = 0, ["y"] = 6, ["z"] = 0, ["name"] = "default:stone"}, {["x"] = 0, ["y"] = 6, ["z"] = 10, ["name"] = "default:stone"}, {["x"] = 0, ["y"] = 7, ["z"] = 0, ["name"] = "default:stone"}, {["x"] = 0, ["y"] = 7, ["z"] = 10, ["name"] = "default:stone"}, {["x"] = 0, ["y"] = 8, ["z"] = 0, ["name"] = "default:stone"}, {["x"] = 0, ["y"] = 8, ["z"] = 10, ["name"] = "default:stone"}, {["x"] = 0, ["y"] = 9, ["z"] = 0, ["name"] = "default:stone"}, {["x"] = 0, ["y"] = 9, ["z"] = 10, ["name"] = "default:stone"}, {["x"] = 0, ["y"] = 10, ["z"] = 0, ["name"] = "default:stone"}, {["x"] = 0, ["y"] = 10, ["z"] = 1, ["name"] = "default:stone"}, {["x"] = 0, ["y"] = 10, ["z"] = 2, ["name"] = "default:stone"}, {["x"] = 0, ["y"] = 10, ["z"] = 3, ["name"] = "default:stone"}, {["x"] = 0, ["y"] = 10, ["z"] = 4, ["name"] = "default:stone"}, {["x"] = 0, ["y"] = 10, ["z"] = 5, ["name"] = "default:stone"}, {["x"] = 0, ["y"] = 10, ["z"] = 6, ["name"] = "default:stone"}, {["x"] = 0, ["y"] = 10, ["z"] = 7, ["name"] = "default:stone"}, {["x"] = 0, ["y"] = 10, ["z"] = 8, ["name"] = "default:stone"}, {["x"] = 0, ["y"] = 10, ["z"] = 9, ["name"] = "default:stone"}, {["x"] = 0, ["y"] = 10, ["z"] = 10, ["name"] = "default:stone"}, {["x"] = 1, ["y"] = 0, ["param1"] = 15, ["z"] = 0, ["name"] = "default:stone"}, {["x"] = 1, ["y"] = 0, ["param1"] = 15, ["z"] = 1, ["name"] = "default:stone"}, {["x"] = 1, ["y"] = 0, ["param1"] = 15, ["z"] = 2, ["name"] = "default:stone"}, {["x"] = 1, ["y"] = 0, ["param1"] = 15, ["z"] = 3, ["name"] = "default:stone"}, {["x"] = 1, ["y"] = 0, ["param1"] = 15, ["z"] = 4, ["name"] = "default:stone"}, {["x"] = 1, ["y"] = 0, ["param1"] = 15, ["z"] = 5, ["name"] = "default:stone"}, {["x"] = 1, ["y"] = 0, ["param1"] = 15, ["z"] = 6, ["name"] = "default:stone"}, {["x"] = 1, ["y"] = 0, ["param1"] = 15, ["z"] = 7, ["name"] = "default:stone"}, {["x"] = 1, ["y"] = 0, ["param1"] = 15, ["z"] = 8, ["name"] = "default:stone"}, {["x"] = 1, ["y"] = 0, ["param1"] = 15, ["z"] = 9, ["name"] = "default:stone"}, {["x"] = 1, ["y"] = 0, ["param1"] = 15, ["z"] = 10, ["name"] = "default:stone"}, {["x"] = 1, ["y"] = 10, ["z"] = 0, ["name"] = "default:stone"}, {["x"] = 1, ["y"] = 10, ["z"] = 10, ["name"] = "default:stone"}, {["x"] = 2, ["y"] = 0, ["param1"] = 15, ["z"] = 0, ["name"] = "default:stone"}, {["x"] = 2, ["y"] = 0, ["param1"] = 15, ["z"] = 1, ["name"] = "default:stone"}, {["x"] = 2, ["y"] = 0, ["param1"] = 15, ["z"] = 2, ["name"] = "default:stone"}, {["x"] = 2, ["y"] = 0, ["param1"] = 15, ["z"] = 3, ["name"] = "default:stone"}, {["x"] = 2, ["y"] = 0, ["param1"] = 15, ["z"] = 4, ["name"] = "default:stone"}, {["x"] = 2, ["y"] = 0, ["param1"] = 15, ["z"] = 5, ["name"] = "default:stone"}, {["x"] = 2, ["y"] = 0, ["param1"] = 15, ["z"] = 6, ["name"] = "default:stone"}, {["x"] = 2, ["y"] = 0, ["param1"] = 15, ["z"] = 7, ["name"] = "default:stone"}, {["x"] = 2, ["y"] = 0, ["param1"] = 15, ["z"] = 8, ["name"] = "default:stone"}, {["x"] = 2, ["y"] = 0, ["param1"] = 15, ["z"] = 9, ["name"] = "default:stone"}, {["x"] = 2, ["y"] = 0, ["param1"] = 15, ["z"] = 10, ["name"] = "default:stone"}, {["x"] = 2, ["y"] = 10, ["z"] = 0, ["name"] = "default:stone"}, {["x"] = 2, ["y"] = 10, ["z"] = 10, ["name"] = "default:stone"}, {["x"] = 3, ["y"] = 0, ["param1"] = 15, ["z"] = 0, ["name"] = "default:stone"}, {["x"] = 3, ["y"] = 0, ["param1"] = 15, ["z"] = 1, ["name"] = "default:stone"}, {["x"] = 3, ["y"] = 0, ["param1"] = 15, ["z"] = 2, ["name"] = "default:stone"}, {["x"] = 3, ["y"] = 0, ["param1"] = 15, ["z"] = 3, ["name"] = "default:stone"}, {["x"] = 3, ["y"] = 0, ["param1"] = 15, ["z"] = 4, ["name"] = "default:stone"}, {["x"] = 3, ["y"] = 0, ["param1"] = 15, ["z"] = 5, ["name"] = "default:stone"}, {["x"] = 3, ["y"] = 0, ["param1"] = 15, ["z"] = 6, ["name"] = "default:stone"}, {["x"] = 3, ["y"] = 0, ["param1"] = 15, ["z"] = 7, ["name"] = "default:stone"}, {["x"] = 3, ["y"] = 0, ["param1"] = 15, ["z"] = 8, ["name"] = "default:stone"}, {["x"] = 3, ["y"] = 0, ["param1"] = 15, ["z"] = 9, ["name"] = "default:stone"}, {["x"] = 3, ["y"] = 0, ["param1"] = 15, ["z"] = 10, ["name"] = "default:stone"}, {["x"] = 3, ["y"] = 1, ["param1"] = 78, ["z"] = 2, ["name"] = "technic:hv_cable"}, {["x"] = 3, ["meta"] = {["fields"] = {["infotext"] = "Arrayed Solar HV Generator Active (4900 EU)", ["HV_EU_supply"] = "4900"}, ["inventory"] = {}}, ["y"] = 2, ["param1"] = 94, ["z"] = 2, ["name"] = "technic:solar_array_hv"}, {["x"] = 3, ["y"] = 10, ["z"] = 0, ["name"] = "default:stone"}, {["x"] = 3, ["y"] = 10, ["z"] = 10, ["name"] = "default:stone"}, {["x"] = 4, ["y"] = 0, ["param1"] = 15, ["z"] = 0, ["name"] = "default:stone"}, {["x"] = 4, ["y"] = 0, ["param1"] = 15, ["z"] = 1, ["name"] = "default:stone"}, {["x"] = 4, ["y"] = 0, ["param1"] = 15, ["z"] = 2, ["name"] = "default:stone"}, {["x"] = 4, ["y"] = 0, ["param1"] = 15, ["z"] = 3, ["name"] = "default:stone"}, {["x"] = 4, ["y"] = 0, ["param1"] = 15, ["z"] = 4, ["name"] = "default:stone"}, {["x"] = 4, ["y"] = 0, ["param1"] = 15, ["z"] = 5, ["name"] = "default:stone"}, {["x"] = 4, ["y"] = 0, ["param1"] = 15, ["z"] = 6, ["name"] = "default:stone"}, {["x"] = 4, ["y"] = 0, ["param1"] = 15, ["z"] = 7, ["name"] = "default:stone"}, {["x"] = 4, ["y"] = 0, ["param1"] = 15, ["z"] = 8, ["name"] = "default:stone"}, {["x"] = 4, ["y"] = 0, ["param1"] = 15, ["z"] = 9, ["name"] = "default:stone"}, {["x"] = 4, ["y"] = 0, ["param1"] = 15, ["z"] = 10, ["name"] = "default:stone"}, {["x"] = 4, ["y"] = 1, ["param1"] = 94, ["z"] = 2, ["name"] = "technic:hv_cable"}, {["x"] = 4, ["meta"] = {["fields"] = {["infotext"] = "Arrayed Solar HV Generator Active (4900 EU)", ["HV_EU_supply"] = "4900"}, ["inventory"] = {}}, ["y"] = 2, ["param1"] = 110, ["z"] = 2, ["name"] = "technic:solar_array_hv"}, {["x"] = 4, ["y"] = 10, ["z"] = 0, ["name"] = "default:stone"}, {["x"] = 4, ["y"] = 10, ["z"] = 10, ["name"] = "default:stone"}, {["x"] = 5, ["y"] = 0, ["param1"] = 15, ["z"] = 0, ["name"] = "default:stone"}, {["x"] = 5, ["y"] = 0, ["param1"] = 15, ["z"] = 1, ["name"] = "default:stone"}, {["x"] = 5, ["y"] = 0, ["param1"] = 15, ["z"] = 2, ["name"] = "default:stone"}, {["x"] = 5, ["y"] = 0, ["param1"] = 15, ["z"] = 3, ["name"] = "default:stone"}, {["x"] = 5, ["y"] = 0, ["param1"] = 15, ["z"] = 4, ["name"] = "default:stone"}, {["x"] = 5, ["y"] = 0, ["param1"] = 15, ["z"] = 5, ["name"] = "default:stone"}, {["x"] = 5, ["y"] = 0, ["param1"] = 15, ["z"] = 6, ["name"] = "default:stone"}, {["x"] = 5, ["y"] = 0, ["param1"] = 15, ["z"] = 7, ["name"] = "default:stone"}, {["x"] = 5, ["y"] = 0, ["param1"] = 15, ["z"] = 8, ["name"] = "default:stone"}, {["x"] = 5, ["y"] = 0, ["param1"] = 15, ["z"] = 9, ["name"] = "default:stone"}, {["x"] = 5, ["y"] = 0, ["param1"] = 15, ["z"] = 10, ["name"] = "default:stone"}, {["x"] = 5, ["y"] = 1, ["param1"] = 109, ["z"] = 2, ["name"] = "technic:hv_cable"}, {["x"] = 5, ["y"] = 1, ["param1"] = 126, ["z"] = 3, ["name"] = "technic:hv_cable"}, {["x"] = 5, ["y"] = 1, ["param1"] = 142, ["z"] = 4, ["name"] = "technic:hv_cable"}, {["x"] = 5, ["y"] = 1, ["param1"] = 158, ["z"] = 5, ["name"] = "technic:hv_cable"}, {["x"] = 5, ["meta"] = {["fields"] = {["infotext"] = "Switching Station. Supply: 19.6 kEU Demand: 2500 EU", ["formspec"] = "field[channel;Channel;${channel}]"}, ["inventory"] = {}}, ["y"] = 2, ["z"] = 2, ["name"] = "technic:switching_station"}, {["x"] = 5, ["meta"] = {["fields"] = {["HV_EU_input"] = "8550", ["HV_EU_demand"] = "100000", ["infotext"] = "HV Battery Box: 680.3 kEU / 1000 kEU", ["formspec"] = "size[8,9]image[1,1;1,2;technic_power_meter_bg.png]list[context;src;3,1;1,1;]image[4,1;1,1;technic_battery_reload.png]list[context;dst;5,1;1,1;]label[0,0;HV Battery Box]label[3,0;Charge]label[5,0;Discharge]label[1,3;Power level]list[current_player;main;0,5;8,4;]listring[context;dst]listring[current_player;main]listring[context;src]listring[current_player;main]list[context;upgrade1;3.5,3;1,1;]list[context;upgrade2;4.5,3;1,1;]label[3.5,4;Upgrade Slots]listring[context;upgrade1]listring[current_player;main]listring[context;upgrade2]listring[current_player;main]image[1,1;1,2;technic_power_meter_bg.png^[lowpart:0:technic_power_meter_fg.png]", ["internal_EU_charge"] = "680298", ["internal_EU_charge_max"] = "1000000", ["last_side_shown"] = "6", ["HV_EU_supply"] = "400000"}, ["inventory"] = {["upgrade2"] = {""}, ["src"] = {""}, ["upgrade1"] = {""}, ["dst"] = {""}}}, ["param2"] = 3, ["y"] = 2, ["z"] = 3, ["name"] = "technic:hv_battery_box6"}, {["x"] = 5, ["meta"] = {["fields"] = {["HV_EU_input"] = "8550", ["HV_EU_demand"] = "100000", ["infotext"] = "HV Battery Box: 671.7 kEU / 1000 kEU", ["formspec"] = "size[8,9]image[1,1;1,2;technic_power_meter_bg.png]list[context;src;3,1;1,1;]image[4,1;1,1;technic_battery_reload.png]list[context;dst;5,1;1,1;]label[0,0;HV Battery Box]label[3,0;Charge]label[5,0;Discharge]label[1,3;Power level]list[current_player;main;0,5;8,4;]listring[context;dst]listring[current_player;main]listring[context;src]listring[current_player;main]list[context;upgrade1;3.5,3;1,1;]list[context;upgrade2;4.5,3;1,1;]label[3.5,4;Upgrade Slots]listring[context;upgrade1]listring[current_player;main]listring[context;upgrade2]listring[current_player;main]image[1,1;1,2;technic_power_meter_bg.png^[lowpart:0:technic_power_meter_fg.png]", ["internal_EU_charge"] = "680298", ["internal_EU_charge_max"] = "1000000", ["last_side_shown"] = "6", ["HV_EU_supply"] = "400000"}, ["inventory"] = {["upgrade2"] = {""}, ["src"] = {""}, ["upgrade1"] = {""}, ["dst"] = {""}}}, ["param2"] = 3, ["y"] = 2, ["z"] = 4, ["name"] = "technic:hv_battery_box6"}, {["x"] = 5, ["y"] = 2, ["param1"] = 174, ["z"] = 5, ["name"] = "technic:hv_cable"}, {["x"] = 5, ["y"] = 3, ["param1"] = 190, ["z"] = 5, ["name"] = "technic:hv_cable"}, {["x"] = 5, ["y"] = 4, ["param1"] = 206, ["z"] = 5, ["name"] = "technic:hv_cable"}, {["x"] = 5, ["meta"] = {["fields"] = {["power_requirement"] = "2500", ["HV_EU_demand"] = "2500", ["formspec"] = "size[8,10.55;]field[0.3,0.5;2,1;x;X;-148]field[2.3,0.5;2,1;y;Y;38]field[4.3,0.5;2,1;z;Z;275]field[6.3,0.5;2,1;radius;Radius;5]button_exit[0,1;2,1;jump;Jump]button_exit[2,1;2,1;show;Show]button_exit[4,1;2,1;save;Save]button[6,1;2,1;reset;Reset]button[0,2;4,1;write_book;Write to book]button[4,2;4,1;read_book;Read from bookmark]list[context;main;0,3.25;8,1;]list[current_player;main;0,5.75;8,4;]field[4.3,10.27;3.2,1;digiline_channel;Digiline channel;]button_exit[7,9.95;1,1;set_digiline_channel;Set]listring[context;main]listring[current_player;main]label[3,4.7;Upgrades]list[context;upgrade;4,4.5;4,1;]", ["y"] = "38", ["x"] = "-148", ["owner"] = "singleplayer", ["channel"] = "jumpdrive", ["HV_EU_input"] = "2500", ["z"] = "275", ["infotext"] = "Power: 2500/2500 Store: 202500/1000000", ["max_powerstorage"] = "1000000", ["radius"] = "5", ["powerstorage"] = "202500"}, ["inventory"] = {["main"] = {"", "", "", "", "", "", "", ""}, ["upgrade"] = {"", "", "", ""}}}, ["y"] = 5, ["z"] = 5, ["name"] = "jumpdrive:engine"}, {["x"] = 5, ["y"] = 10, ["z"] = 0, ["name"] = "default:stone"}, {["x"] = 5, ["y"] = 10, ["z"] = 10, ["name"] = "default:stone"}, {["x"] = 6, ["y"] = 0, ["param1"] = 15, ["z"] = 0, ["name"] = "default:stone"}, {["x"] = 6, ["y"] = 0, ["param1"] = 15, ["z"] = 1, ["name"] = "default:stone"}, {["x"] = 6, ["y"] = 0, ["param1"] = 15, ["z"] = 2, ["name"] = "default:stone"}, {["x"] = 6, ["y"] = 0, ["param1"] = 15, ["z"] = 3, ["name"] = "default:stone"}, {["x"] = 6, ["y"] = 0, ["param1"] = 15, ["z"] = 4, ["name"] = "default:stone"}, {["x"] = 6, ["y"] = 0, ["param1"] = 15, ["z"] = 5, ["name"] = "default:stone"}, {["x"] = 6, ["y"] = 0, ["param1"] = 15, ["z"] = 6, ["name"] = "default:stone"}, {["x"] = 6, ["y"] = 0, ["param1"] = 15, ["z"] = 7, ["name"] = "default:stone"}, {["x"] = 6, ["y"] = 0, ["param1"] = 15, ["z"] = 8, ["name"] = "default:stone"}, {["x"] = 6, ["y"] = 0, ["param1"] = 15, ["z"] = 9, ["name"] = "default:stone"}, {["x"] = 6, ["y"] = 0, ["param1"] = 15, ["z"] = 10, ["name"] = "default:stone"}, {["x"] = 6, ["y"] = 1, ["param1"] = 94, ["z"] = 2, ["name"] = "technic:hv_cable"}, {["x"] = 6, ["meta"] = {["fields"] = {["infotext"] = "Arrayed Solar HV Generator Active (4900 EU)", ["HV_EU_supply"] = "4900"}, ["inventory"] = {}}, ["y"] = 2, ["param1"] = 110, ["z"] = 2, ["name"] = "technic:solar_array_hv"}, {["x"] = 6, ["y"] = 10, ["z"] = 0, ["name"] = "default:stone"}, {["x"] = 6, ["y"] = 10, ["z"] = 10, ["name"] = "default:stone"}, {["x"] = 7, ["y"] = 0, ["param1"] = 15, ["z"] = 0, ["name"] = "default:stone"}, {["x"] = 7, ["y"] = 0, ["param1"] = 15, ["z"] = 1, ["name"] = "default:stone"}, {["x"] = 7, ["y"] = 0, ["param1"] = 15, ["z"] = 2, ["name"] = "default:stone"}, {["x"] = 7, ["y"] = 0, ["param1"] = 15, ["z"] = 3, ["name"] = "default:stone"}, {["x"] = 7, ["y"] = 0, ["param1"] = 15, ["z"] = 4, ["name"] = "default:stone"}, {["x"] = 7, ["y"] = 0, ["param1"] = 15, ["z"] = 5, ["name"] = "default:stone"}, {["x"] = 7, ["y"] = 0, ["param1"] = 15, ["z"] = 6, ["name"] = "default:stone"}, {["x"] = 7, ["y"] = 0, ["param1"] = 15, ["z"] = 7, ["name"] = "default:stone"}, {["x"] = 7, ["y"] = 0, ["param1"] = 15, ["z"] = 8, ["name"] = "default:stone"}, {["x"] = 7, ["y"] = 0, ["param1"] = 15, ["z"] = 9, ["name"] = "default:stone"}, {["x"] = 7, ["y"] = 0, ["param1"] = 15, ["z"] = 10, ["name"] = "default:stone"}, {["x"] = 7, ["y"] = 1, ["param1"] = 78, ["z"] = 2, ["name"] = "technic:hv_cable"}, {["x"] = 7, ["meta"] = {["fields"] = {["infotext"] = "Arrayed Solar HV Generator Active (4900 EU)", ["HV_EU_supply"] = "4900"}, ["inventory"] = {}}, ["y"] = 2, ["param1"] = 94, ["z"] = 2, ["name"] = "technic:solar_array_hv"}, {["x"] = 7, ["y"] = 10, ["z"] = 0, ["name"] = "default:stone"}, {["x"] = 7, ["y"] = 10, ["z"] = 10, ["name"] = "default:stone"}, {["x"] = 8, ["y"] = 0, ["param1"] = 15, ["z"] = 0, ["name"] = "default:stone"}, {["x"] = 8, ["y"] = 0, ["param1"] = 15, ["z"] = 1, ["name"] = "default:stone"}, {["x"] = 8, ["y"] = 0, ["param1"] = 15, ["z"] = 2, ["name"] = "default:stone"}, {["x"] = 8, ["y"] = 0, ["param1"] = 15, ["z"] = 3, ["name"] = "default:stone"}, {["x"] = 8, ["y"] = 0, ["param1"] = 15, ["z"] = 4, ["name"] = "default:stone"}, {["x"] = 8, ["y"] = 0, ["param1"] = 15, ["z"] = 5, ["name"] = "default:stone"}, {["x"] = 8, ["y"] = 0, ["param1"] = 15, ["z"] = 6, ["name"] = "default:stone"}, {["x"] = 8, ["y"] = 0, ["param1"] = 15, ["z"] = 7, ["name"] = "default:stone"}, {["x"] = 8, ["y"] = 0, ["param1"] = 15, ["z"] = 8, ["name"] = "default:stone"}, {["x"] = 8, ["y"] = 0, ["param1"] = 15, ["z"] = 9, ["name"] = "default:stone"}, {["x"] = 8, ["y"] = 0, ["param1"] = 15, ["z"] = 10, ["name"] = "default:stone"}, {["x"] = 8, ["y"] = 10, ["z"] = 0, ["name"] = "default:stone"}, {["x"] = 8, ["y"] = 10, ["z"] = 10, ["name"] = "default:stone"}, {["x"] = 9, ["y"] = 0, ["param1"] = 15, ["z"] = 0, ["name"] = "default:stone"}, {["x"] = 9, ["y"] = 0, ["param1"] = 15, ["z"] = 1, ["name"] = "default:stone"}, {["x"] = 9, ["y"] = 0, ["param1"] = 15, ["z"] = 2, ["name"] = "default:stone"}, {["x"] = 9, ["y"] = 0, ["param1"] = 15, ["z"] = 3, ["name"] = "default:stone"}, {["x"] = 9, ["y"] = 0, ["param1"] = 15, ["z"] = 4, ["name"] = "default:stone"}, {["x"] = 9, ["y"] = 0, ["param1"] = 15, ["z"] = 5, ["name"] = "default:stone"}, {["x"] = 9, ["y"] = 0, ["param1"] = 15, ["z"] = 6, ["name"] = "default:stone"}, {["x"] = 9, ["y"] = 0, ["param1"] = 15, ["z"] = 7, ["name"] = "default:stone"}, {["x"] = 9, ["y"] = 0, ["param1"] = 15, ["z"] = 8, ["name"] = "default:stone"}, {["x"] = 9, ["y"] = 0, ["param1"] = 15, ["z"] = 9, ["name"] = "default:stone"}, {["x"] = 9, ["y"] = 0, ["param1"] = 15, ["z"] = 10, ["name"] = "default:stone"}, {["x"] = 9, ["y"] = 10, ["z"] = 0, ["name"] = "default:stone"}, {["x"] = 9, ["y"] = 10, ["z"] = 10, ["name"] = "default:stone"}, {["x"] = 10, ["y"] = 0, ["param1"] = 15, ["z"] = 0, ["name"] = "default:stone"}, {["x"] = 10, ["y"] = 0, ["param1"] = 15, ["z"] = 1, ["name"] = "default:stone"}, {["x"] = 10, ["y"] = 0, ["param1"] = 15, ["z"] = 2, ["name"] = "default:stone"}, {["x"] = 10, ["y"] = 0, ["param1"] = 15, ["z"] = 3, ["name"] = "default:stone"}, {["x"] = 10, ["y"] = 0, ["param1"] = 15, ["z"] = 4, ["name"] = "default:stone"}, {["x"] = 10, ["y"] = 0, ["param1"] = 15, ["z"] = 5, ["name"] = "default:stone"}, {["x"] = 10, ["y"] = 0, ["param1"] = 15, ["z"] = 6, ["name"] = "default:stone"}, {["x"] = 10, ["y"] = 0, ["param1"] = 15, ["z"] = 7, ["name"] = "default:stone"}, {["x"] = 10, ["y"] = 0, ["param1"] = 15, ["z"] = 8, ["name"] = "default:stone"}, {["x"] = 10, ["y"] = 0, ["param1"] = 15, ["z"] = 9, ["name"] = "default:stone"}, {["x"] = 10, ["y"] = 0, ["param1"] = 15, ["z"] = 10, ["name"] = "default:stone"}, {["x"] = 10, ["y"] = 1, ["z"] = 0, ["name"] = "default:stone"}, {["x"] = 10, ["y"] = 1, ["z"] = 10, ["name"] = "default:stone"}, {["x"] = 10, ["y"] = 2, ["z"] = 0, ["name"] = "default:stone"}, {["x"] = 10, ["y"] = 2, ["z"] = 10, ["name"] = "default:stone"}, {["x"] = 10, ["y"] = 3, ["z"] = 0, ["name"] = "default:stone"}, {["x"] = 10, ["y"] = 3, ["z"] = 10, ["name"] = "default:stone"}, {["x"] = 10, ["y"] = 4, ["z"] = 0, ["name"] = "default:stone"}, {["x"] = 10, ["y"] = 4, ["z"] = 10, ["name"] = "default:stone"}, {["x"] = 10, ["y"] = 5, ["z"] = 0, ["name"] = "default:stone"}, {["x"] = 10, ["y"] = 5, ["z"] = 10, ["name"] = "default:stone"}, {["x"] = 10, ["y"] = 6, ["z"] = 0, ["name"] = "default:stone"}, {["x"] = 10, ["y"] = 6, ["z"] = 10, ["name"] = "default:stone"}, {["x"] = 10, ["y"] = 7, ["z"] = 0, ["name"] = "default:stone"}, {["x"] = 10, ["y"] = 7, ["z"] = 10, ["name"] = "default:stone"}, {["x"] = 10, ["y"] = 8, ["z"] = 0, ["name"] = "default:stone"}, {["x"] = 10, ["y"] = 8, ["z"] = 10, ["name"] = "default:stone"}, {["x"] = 10, ["y"] = 9, ["z"] = 0, ["name"] = "default:stone"}, {["x"] = 10, ["y"] = 9, ["z"] = 10, ["name"] = "default:stone"}, {["x"] = 10, ["y"] = 10, ["z"] = 0, ["name"] = "default:stone"}, {["x"] = 10, ["y"] = 10, ["z"] = 1, ["name"] = "default:stone"}, {["x"] = 10, ["y"] = 10, ["z"] = 2, ["name"] = "default:stone"}, {["x"] = 10, ["y"] = 10, ["z"] = 3, ["name"] = "default:stone"}, {["x"] = 10, ["y"] = 10, ["z"] = 4, ["name"] = "default:stone"}, {["x"] = 10, ["y"] = 10, ["z"] = 5, ["name"] = "default:stone"}, {["x"] = 10, ["y"] = 10, ["z"] = 6, ["name"] = "default:stone"}, {["x"] = 10, ["y"] = 10, ["z"] = 7, ["name"] = "default:stone"}, {["x"] = 10, ["y"] = 10, ["z"] = 8, ["name"] = "default:stone"}, {["x"] = 10, ["y"] = 10, ["z"] = 9, ["name"] = "default:stone"}, {["x"] = 10, ["y"] = 10, ["z"] = 10, ["name"] = "default:stone"}}